Workbook
Name _: #REF!
Name _: #REF!
Name _: #REF!
Name _: #REF!
Name _: #REF!
Name _?__POINT: #REF!
Name _?_컛?___i: #REF!
Name _?CWHL: #REF!
Name _?쨲?f: #REF!
Name __?: #REF!
Name __?_컛?___i: #REF!
Name __?쨲?f: #REF!
Name ___?: #REF!
Name ___?쨲?f: #REF!
Name ____?: #REF!
Name ____?_컛?___i: #REF!
Name ____?쨲?f: #REF!
Name _____?쨲?f: #REF!
Name ______?쨲?f: #REF!
Name _______?쨲?f: #REF!
Name ________?쨲?f: #REF!
Name _____________?: #REF!
Name _____________?_컛?___i: #REF!
Name ____________________?: #REF!
Name ____________________?_컛?___i: #REF!
Name _____________________a1: #REF!
Name _____________________a2: #REF!
Name _____________________a3: #REF!
Name ____________________abs710: #REF!
Name ____________________abs99: #REF!
Name ____________________b1: #REF!
Name ____________________D3: #REF!
Name ____________________d31: #REF!
Name ____________________FF3: #REF!
Name ____________________G1: #REF!
Name ____________________NG3: #REF!
Name ____________________NG4: #REF!
Name ____________________NG5: #REF!
Name ____________________SDW1: #REF!
Name ______________a1: #REF!
Name ______________a2: #REF!
Name _____________abs710: #REF!
Name _____________abs99: #REF!
Name _____________b1: #REF!
Name _____________D3: #REF!
Name _____________d31: #REF!
Name _____________FF3: #REF!
Name _____________G1: #REF!
Name _____________NG3: #REF!
Name _____________NG4: #REF!
Name _____________NG5: #REF!
Name _____________SDW1: #REF!
Name ________01: '[2]#REF'!#REF!
Name ________02: '[2]#REF'!#REF!
Name ________03: '[2]#REF'!#REF!
Name ________04: '[2]#REF'!#REF!
Name ________05: '[2]#REF'!#REF!
Name ________06: '[2]#REF'!#REF!
Name ________DAT1: #REF!
Name ________DAT10: #REF!

Sheet summary
A1: A. 재무적 검토 (경제성 평가)
A3: 1. 프로젝트 개요
A4: 주식회사 신라공업은 Connector housing ass라는 제품을 SK 고객으로부터 견적요청을 받아 견적을 제출하고자 합니다.
A6: 2. 기본 정보 및 견적 제시가
A7: 연도 | B7: ='Commercial Input'!C13 -> 2028 | C7: ='Commercial Input'!D13 -> 2029 | D7: ='Commercial Input'!E13 -> 2030 | E7: ='Commercial Input'!F13 -> 2031 | F7: ='Commercial Input'!G13 -> 2032 | G7: ='Commercial Input'!H13 -> 2033 | H7: ='Commercial Input'!I13 -> 2034 | I7: ='Commercial Input'!J13 -> 2035
A8: 판매량 | B8: ='Commercial Input'!C14 -> 800000 | C8: ='Commercial Input'!D14 -> 800000 | D8: ='Commercial Input'!E14 -> 800000 | E8: ='Commercial Input'!F14 -> 800000 | F8: ='Commercial Input'!G14 -> 800000 | G8: ='Commercial Input'!H14 -> 800000 | H8: ='Commercial Input'!I14 -> 800000 | I8: ='Commercial Input'!J14 -> 0
A9: Minimum efficient scope | B9: ='Process input'!$J$50 -> 1028160 | C9: ='Process input'!$J$50 -> 1028160 | D9: ='Process input'!$J$50 -> 1028160 | E9: ='Process input'!$J$50 -> 1028160 | F9: ='Process input'!$J$50 -> 1028160 | G9: ='Process input'!$J$50 -> 1028160 | H9: ='Process input'!$J$50 -> 1028160 | I9: ='Process input'!$J$50 -> 1028160
A10: 연도별 견적 제시가격 (제품 1단위당) | B10: ='Commercial Input'!C17 -> 1200 | C10: ='Commercial Input'!D17 -> 1200 | D10: ='Commercial Input'!E17 -> 1200 | E10: ='Commercial Input'!F17 -> 1200 | F10: ='Commercial Input'!G17 -> 1200 | G10: ='Commercial Input'!H17 -> 1200 | H10: ='Commercial Input'!I17 -> 1200 | I10: ='Commercial Input'!J17 -> 0
A12: 3. 신라공업의 최소요구 수익률 | B12: 0.1697
A14: 4. 순운전 자본 조건
B15: 구분 | C15: 원소재 재고 | D15: 재공품 | E15: 사내완제품 재고 | F15: 고객사 대금 지불 조건 | G15: 신라공업 협력사 대금 지불 조건
B16: 일수 | C16: ='AP 1. Assumption'!B10 -> 30 | D16: ='AP 1. Assumption'!C10 -> 7 | E16: ='AP 1. Assumption'!D10 -> 7 | F16: ='AP 1. Assumption'!E10 -> 60 | G16: ='AP 1. Assumption'!F10 -> 23.676804
B17: Turnover | C17: =264/C16 -> 8.8 | D17: =264/D16 -> 37.714286 | E17: =264/E16 -> 37.714286 | F17: =360/F16 -> 6 | G17: =360/G16 -> 15.204755
A19: 4. 제품 1단위당 원가
A20: 구분 | B20: 연도 | C20: =B7 -> 2028 | D20: =C7 -> 2029 | E20: =D7 -> 2030 | F20: =E7 -> 2031 | G20: =F7 -> 2032 | H20: =G7 -> 2033 | I20: =H7 -> 2034 | J20: =I7 -> 2035
A21: 변동비 | B21: 재료비 | C21: ='Materials input'!P40 -> 440 | D21: ='Materials input'!R40 -> 440 | E21: ='Materials input'!T40 -> 440 | F21: ='Materials input'!V40 -> 440 | G21: ='Materials input'!X40 -> 440 | H21: ='Materials input'!Z40 -> 440 | I21: ='Materials input'!Z40 -> 440
A22: 변동비 | B22: 포장비 | C22: ='Materials input'!P42 -> 15 | D22: ='Materials input'!R42 -> 15 | E22: ='Materials input'!T42 -> 15 | F22: ='Materials input'!V42 -> 15 | G22: ='Materials input'!X42 -> 15 | H22: ='Materials input'!Y42 -> 0 | I22: ='Materials input'!Z42 -> 15
A23: 변동비 | B23: 물류비 | C23: ='Materials input'!P43 -> 15 | D23: ='Materials input'!R43 -> 15 | E23: ='Materials input'!T43 -> 15 | F23: ='Materials input'!V43 -> 15 | G23: ='Materials input'!X43 -> 15 | H23: ='Materials input'!Y43 -> 0 | I23: ='Materials input'!Z43 -> 15
A24: 변동비 | B24: 노무비 | C24: ='Process input'!C56 -> 139.64612 | D24: ='Process input'!D56 -> 146.34914 | E24: ='Process input'!E56 -> 153.3739 | F24: ='Process input'!F56 -> 160.73584 | G24: ='Process input'!G56 -> 168.45116 | H24: ='Process input'!H56 -> 176.53682 | I24: ='Process input'!I56 -> 185.01059
A25: 변동비 | B25: 전력비 | C25: ='Process input'!C57 -> 31.985294 | D25: ='Process input'!D57 -> 31.985294 | E25: ='Process input'!E57 -> 31.985294 | F25: ='Process input'!F57 -> 31.985294 | G25: ='Process input'!G57 -> 31.985294 | H25: ='Process input'!H57 -> 31.985294 | I25: ='Process input'!I57 -> 31.985294
A26: 고정비 | B26: 간접노무비 | C26: ='Process input'!C59 -> 55.858449 | D26: ='Process input'!D59 -> 58.539655 | E26: ='Process input'!E59 -> 61.349558 | F26: ='Process input'!F59 -> 64.294337 | G26: ='Process input'!G59 -> 67.380465 | H26: ='Process input'!H59 -> 70.614728 | I26: ='Process input'!I59 -> 74.004235
A27: 고정비 | B27: 수선비 | C27: ='Process input'!C60 -> 7.4524759 | D27: ='Process input'!D60 -> 7.4524759 | E27: ='Process input'!E60 -> 7.4524759 | F27: ='Process input'!F60 -> 7.4524759 | G27: ='Process input'!G60 -> 7.4524759 | H27: ='Process input'!H60 -> 7.4524759 | I27: ='Process input'!I60 -> 7.4524759
A28: 고정비 | B28: 제조간접비 | C28: ='Process input'!C63 -> 47.998998 | D28: ='Process input'!D63 -> 47.998998 | E28: ='Process input'!E63 -> 47.998998 | F28: ='Process input'!F63 -> 47.998998 | G28: ='Process input'!G63 -> 47.998998 | H28: ='Process input'!H63 -> 47.998998 | I28: ='Process input'!I63 -> 47.998998
A29: 변동비 | B29: 일반관리비 | C29: ='Process input'!C67 -> 88.763028 | D29: ='Process input'!D67 -> 91.109083 | E29: ='Process input'!E67 -> 93.567749 | F29: ='Process input'!F67 -> 96.14443 | G29: ='Process input'!G67 -> 98.844792 | H29: ='Process input'!H67 -> 101.67477 | I29: ='Process input'!I67 -> 104.64059
A30: *노무비와 간접 노무비 매년 상승 가정
A32: 5. 설비 투자비 | B32: ='Commercial Input'!C20 -> 590000000
A34: 6. 설비 투자비 감각 상각계획(내용 연수 투자가 이루어지는 연도부터 7년 / 프로그램 종료후 설비들의 잔존 가치는 없는 것으로 가정함.)
A35: 연도 | B35: =C35-1 -> 2027 | C35: =C20 -> 2028 | D35: =D20 -> 2029 | E35: =E20 -> 2030 | F35: =F20 -> 2031 | G35: =G20 -> 2032 | H35: =H20 -> 2033 | I35: =I20 -> 2034 | J35: =J20 -> 2035
A36: 금액 | B36: =$B$32/7 -> 84285714 | C36: =$B$32/7 -> 84285714 | D36: =$B$32/7 -> 84285714 | E36: =$B$32/7 -> 84285714 | F36: =$B$32/7 -> 84285714 | G36: =$B$32/7 -> 84285714 | H36: =$B$32/7 -> 84285714 | I36: =$B$32/7 -> 84285714
A38: 7. 생산 라인 Capacity | B38: 구분 | C38: =C35 -> 2028 | D38: =D35 -> 2029 | E38: =E35 -> 2030 | F38: =F35 -> 2031 | G38: =G35 -> 2032 | H38: =H35 -> 2033 | I38: =I35 -> 2034 | J38: =J35 -> 2035
B39: 생산라인 연간캐파 | C39: ='Process input'!J50 -> 1028160 | D39: =C39 -> 1028160 | E39: =D39 -> 1028160 | F39: =E39 -> 1028160 | G39: =F39 -> 1028160 | H39: =G39 -> 1028160 | I39: =H39 -> 1028160
B40: 연간 생산량 | C40: =B8 -> 800000 | D40: =C8 -> 800000 | E40: =D8 -> 800000 | F40: =E8 -> 800000 | G40: =F8 -> 800000 | H40: =G8 -> 800000 | I40: =H8 -> 800000
B41: 가동율 | C41: =C40/C39 -> 0.77808901 | D41: =D40/D39 -> 0.77808901 | E41: =E40/E39 -> 0.77808901 | F41: =F40/F39 -> 0.77808901 | G41: =G40/G39 -> 0.77808901 | H41: =H40/H39 -> 0.77808901 | I41: =I40/I39 -> 0.77808901
A43: 8. 초기 R&D 비용 | B43: ='Commercial Input'!E20 -> 0
A44: 9. 금형비
A45: 초기에 금형 업체에 지불하는 금액 | B45: ='Commercial Input'!D22 -> 67200000
A46: 실제 고객에 청구하는 금액 | B46: ='Commercial Input'!C22 -> 80604000
A48: 10. 고객으로부터 프로그램 수주시 지불하는 리베이트 | B48: ='Commercial Input'!C21 -> 0
A50: 11. 연도별 OP
A51: 구분 | B51: =C35 -> 2028 | C51: =D35 -> 2029 | D51: =E35 -> 2030 | E51: =F35 -> 2031 | F51: =G35 -> 2032 | G51: =H35 -> 2033 | H51: =I35 -> 2034 | I51: =J35 -> 2035
...

Sheet Commercial Input
A1: Commercial input
C2: Input the data | D2: Do not touch | E2: Special remark
B5: 작성일 | C5: 46033
A6: Program Info | B6: Program | C6: Connector housing ass | F6: ='AP 3. ROI review'!F96 -> NPV | G6: ='AP 3. ROI review'!G96 -> 343.4026 | H6: 지점 찾기
B7: Customer | C7: SK | F7: ='AP 3. ROI review'!F97 -> IRR | G7: ='AP 3. ROI review'!G97 -> 0.38395849 | H7: 0.23
B8: Part Name | C8: Connector housing ass | F8: 데이터 가상분석을 통해 목표가 찾기 | H8: 0.1697
B9: Part Number | C9: TBD
B10: OEM/Model
B11: Target Price
B12: SOP | C12: 2028 | D12: 0.0051043387 | E12: 0.0049796288 | F12: 0.0050045496 | G12: 0
A13: Shilla Quotation | B13: Year | C13: =C12 -> 2028 | D13: =C13+1 -> 2029 | E13: =D13+1 -> 2030 | F13: =E13+1 -> 2031 | G13: =F13+1 -> 2032 | H13: =G13+1 -> 2033 | I13: =H13+1 -> 2034 | J13: =I13+1 -> 2035 | K13: =J13+1 -> 2036 | ... M13: =L13+1 -> 2038
B14: Quotation Volume | C14: 800000 | D14: 800000 | E14: 800000 | F14: 800000 | G14: 800000 | H14: 800000 | I14: 800000
B15: Minimum efficient scope | C15: ='Process input'!J50 -> 1028160 | D15: ='Process input'!J50 -> 1028160 | E15: =D15 -> 1028160 | F15: =E15 -> 1028160 | G15: =F15 -> 1028160 | H15: =G15 -> 1028160 | I15: =H15 -> 1028160
B16: Quoted Price (USD)
B17: Quoted Price (KRW) | C17: 1200 | D17: 1200 | E17: 1200 | F17: 1200 | G17: 1200 | H17: 1200 | I17: 1200
B18: FX rate
B19: Annual price reduction
B20: Investment(이자제외) | C20: 590000000 | D20: R&D | E20: 0
B21: Business link
B22: Tooling costs | C22: 80604000 | D22: 67200000 | E22: (실제 협력사 지불)
A23: ROI study | B23: Risk free return rate | C23: 0.04069 | D23: 회사채수익률(3년,AA-) ('23.05.10) | F23: 한국은행 경제 통계시스템 | G23: http://ecos.bok.or.kr/jsp/vis/keystat/#/key
B24: Interest Rate for Bank Borrowings | C24: 0.06 | D24: 신라 재무팀 가이드라인
B25: Income Taxes | C25: 0.22 | D25: 신라 재무팀 가이드라인
B26: 2023 expected return for capital | C26: 0.1 | D26: Do not touch | F26: Business today | G26: https://www.businesstoday.in/latest/story/equities-may-deliver-9-12-return-in-2022-pradeep-gupta-co-founder-vc-anand-rathi-group-317038-2021-12-28
B27: Korean Equity risk premium | C27: 0.0679 | D27: Do not touch | F27: 뉴욕대 국가별 프리미엄 자료 | G27: https://pages.stern.nyu.edu/~adamodar/New_Home_Page/datafile/ctryprem.html
B28: Annual fixed costs increase | C28: 0.02 | D28: Do not touch
B29: Benchmark Current beta of the company | C29: 1.28 | D29: Do not touch | F29: 우리산업 | G29: KOSDAQ
B30: Benchmark Marginal tax rate | C30: 0.21 | D30: Do not touch | F30: 우리산업 | G30: KOSDAQ
B31: Benchmark The debt/equity ratio | C31: 1.78 | D31: Do not touch | F31: 우리산업 | G31: KOSDAQ
B32: 신라 FS Asset | C32: 114515457295 | D32: Do not touch | F32: 2022 신라 FS
B33: 신라 FS Borrowings | C33: 68930320933 | D33: Do not touch | F33: 2022 신라 FS
B34: 신라 FS capital | C34: 45585136362 | D34: Do not touch | F34: 2022 신라 FS
B35: Year | C35: 2015 | D35: 2016 | E35: 2017 | F35: 2018 | G35: 2019 | H35: 2020 | I35: 2021 | J35: 2022 | K35: Average
B36: Capital | C36: 24228366456 | D36: 27782828681 | E36: 32362809222 | F36: 36654790935 | G36: 41422398600 | H36: 41014510752 | I36: 45584146787 | J36: 45585136362 | L36: 2022 신라 FS | M36: Do not touch
B37: Net profit | C37: 7677870680 | D37: 10764471775 | E37: 7883490541 | F37: 9552887713 | G37: 7928617665 | H37: 4154503252 | I37: 8625566435 | J37: =3213684549+4618859347 -> 7832543896 | L37: 2022 신라 IS | M37: Do not touch
B38: ROE | C38: =C37/C36 -> 0.31689593 | D38: =D37/D36 -> 0.38745053 | E38: =E37/E36 -> 0.24359723 | F38: =F37/F36 -> 0.26061771 | G38: =G37/G36 -> 0.19140895 | H38: =H37/H36 -> 0.1012935 | I38: =I37/I36 -> 0.18922294 | J38: =J37/J36 -> 0.17182232 | K38: =AVERAGE(C38:J38) -> 0.23278864
H39: COVID 19 Drop
A40: Working Capital | B40: Div. | C40: Payment terms Days | D40: Inventory terms | E40: Payable terms | J40: 2022 순이익 재해 손실 부분 미반영
B41: Applied days | C41: 60 | D41: =360/(D43/D44) -> 71.732528 | E41: =360/(D45/D46) -> 23.676804 | F41: Do not touch
C42: 제기 기준 + 운송 픽업 | D42: (연 매출 / 연 재고자산) | E42: (연 매출원가 / 연 매입채무)
...

Sheet Materials input
A1: Material Input
A3: Quotation review
A4: Description | B4: Specification | C4: Operation | D4: Customer Pass through | E4: BOM | F4: BOM | G4: Name of | H4: Country of | I4: Invoiced | J4: Delivery | K4: Payment | L4: Net Purchasing KRW | M4: Net Purchasing USD | N4: Purchasing price | O4: 1st year | Q4: 2nd year | S4: 3rd year | U4: 4th year | W4: 5th year | Y4: 6th year | AA4: 7th year | AC4: 8th year | AE4: 9th year | AG4: 10th year
D5: Y/N | E5: Usage | F5: Unit | G5: Supplier | H5: Origin | I5: Currency | J5: Incoterms | K5: terms | L5: Price | M5: Price | N5: Unit | O5: Savings | P5: Price | Q5: Savings | R5: Price | S5: Savings | T5: Price | U5: Savings | V5: Price | W5: Savings | X5: Price | Y5: Savings | Z5: Price | AA5: Savings | AB5: Price | AC5: Savings | AD5: Price | AE5: Savings | AF5: Price | AG5: Savings | AH5: Price
A6: AR - Cu LME | E6: 32
A7: BP - AL | B7: ALDC12 | E7: 115
A8: AR - COMMUTATOR | F8: 1
A9: AR - CORE ASM | F9: 1
A10: AR - SHAFT | F10: 1
A11: AR - M/wire 가공비 | F11: 1
A12: AR - Insulator - Upper | F12: 1
A13: AR - Insulator - Lower | F13: 1
A14: YK - YOKE ASM | F14: 1
A15: BP - Base Plate 가공비 | F15: 1
A16: BP - POSITION PIN | F16: 2
A17: BP - B/BEARING | F17: 1
A18: BP - RETAINING RING | F18: 1
A19: BC - DAMPER | F19: 2
... A32: ASM - B/BEARING | F32: 1
A38: NG
AC39: 0 | AD39: =SUM(AD6:AD38)*2% -> 0 | AE39: 0 | AF39: =SUM(AF6:AF38)*2% -> 0
A40: Total | P40: 440 | R40: 440 | T40: 440 | V40: 440 | X40: 440 | Z40: 440 | AB40: 440
L42: Packaging | M42: Packaging | P42: 15 | R42: 15 | T42: 15 | V42: 15 | X42: 15 | Z42: 15 | AB42: 15
L43: Logistics | M43: Logistics | P43: 15 | R43: 15 | T43: 15 | V43: 15 | X43: 15 | Z43: 15 | AB43: 15

Sheet Process input
A4: Quotated Production Volume (생산 수량) / year | D4: 800000
A7: Supplier Production Schedule (양산 생산 일정)
B9: Net Available Time (hrs) / Shift | D9: =D10-D11 -> 20.6 | I9: =I10-I11 -> 10.3 | O9: =O10-O11 -> 10.3
B10: Hours / Shifts | D10: =I10+O10 -> 23.6 | F10: Hours / 1st Shift | I10: 11.8 | K10: Hours / 2nd Shift | O10: 11.8
B11: Planned Downtime | D11: =SUM(I11,O11,W11) -> 3 | F11: Planned Downtime | I11: =SUM(I12:I16) -> 1.5 | K11: Planned Downtime | O11: =SUM(O12:O16) -> 1.5
B12: - Lunch Time (hour) 점심 | D12: =I12+O12 -> 1.3333333 | F12: - Lunch Time (Hours) | I12: =40/60 -> 0.66666667 | K12: - Lunch Time (Hours) | O12: =40/60 -> 0.66666667
B13: - Break time (hour) 휴식 | D13: =I13+O13 -> 0.66666667 | F13: - Break time (Hours) | I13: =20/60 -> 0.33333333 | K13: - Break time (Hours) | O13: =20/60 -> 0.33333333
B14: - Dinner Time(hour) 저녁 | D14: =I14+O14 -> 1 | F14: - Dinner Time(Hours) | I14: =30/60 -> 0.5 | K14: - Dinner Time(Hours) | O14: =30/60 -> 0.5
B15: - Fast Response meeting (hour) ect…미팅 | D15: =I15+O15 -> 0 | F15: - Fast Response meeting ect… | K15: - Fast Response meeting ect…
B16: - Shift Change Time (주/야간 변경시 시간) | D16: =I16+O16 -> 0 | F16: - Shift Change Time | K16: - Shift Change Time
B18: days / Week | D18: 5
B19: Weeks / Year (53 Weeks) | D19: 48
B20: Total Available Time (hrs) / year | D20: =D19*D18*D9 -> 4944
A22: Tack Time (minutes) | D22: =(D20*60)/D4 -> 0.3708 | F22: OEE 85% ideal cycle time
A23: Tack Time (Seconds) | D23: =D22*60 -> 22.248 | F23: =D23*0.85 -> 18.9108
X24: 연 임금 상승률
X25: 0.048
A27: 공정 No | B27: 공정 | C27: Cavity | D27: Cycle time | E27: 효율 | F27: UPH | G27: 연작업일수 | H27: Shift | I27: 시간 | J27: 캐파 | K27: 수요볼륨 | L27: 잔여캐파 | M27: Utilization | N27: 투자비 | S27: 전력비 | W27: 직접 노무비
N28: Type | O28: 금액 | P28: 수량 | Q28: 총 투자비 | R28: 금액/unit (7년 상각) | S28: 설비 KWh | T28: KW당 전력비 | U28: 금액/unit | V28: 금액/Year | W28: 작업자 | X28: Hourly rate | Y28: 금액/unit | Z28: 금액/Year
A30: #10 | B30: Terminla cutting and toolig core insertion | C30: 1 | D30: 15 | E30: 0.85 | F30: =3600/D30*C30*E30 -> 204 | G30: =5*48 -> 240 | H30: 2 | I30: 10.5 | J30: =I30*G30*F30*H30 -> 1028160 | K30: =$D$4 -> 800000 | L30: =J30-K30 -> 228160 | M30: =K30/J30 -> 0.77808901 | N30: Specific | O30: 180000000 | P30: 1 | Q30: =O30*P30 -> 180000000 | R30: =Q30/12/22/7/10.5/F30/2 -> 22.736367 | S30: 5 | T30: 145 | U30: =S30*T30/F30 -> 3.5539216 | V30: =U30*K30 -> 2843137.3 | W30: 0 | X30: =24750*1.048*1.048*1.048 -> 28487.809 | Y30: =W30*X30/F30 -> 0 | Z30: =Y30*J30 -> 0
A31: #20 | B31: Insert molding | C31: 4 | D31: 60 | E31: 0.85 | F31: =3600/D31*C31*E31 -> 204 | G31: =5*48 -> 240 | H31: 2 | I31: 10.5 | J31: =I31*G31*F31*H31 -> 1028160 | K31: =$D$4 -> 800000 | L31: =J31-K31 -> 228160 | M31: =K31/J31 -> 0.77808901 | N31: Generic | O31: 210000000 | P31: 1 | Q31: =O31*P31 -> 210000000 | R31: =Q31/12/22/7/10.5/F31/2 -> 26.525762 | S31: 30 | T31: 145 | U31: =S31*T31/F31 -> 21.323529 | V31: =U31*K31 -> 17058824 | W31: 0 | X31: =24750*1.048*1.048*1.048 -> 28487.809 | Y31: =W31*X31/F31 -> 0
A32: #30 | B32: Insert laoding and unloading | C32: 1 | D32: 15 | E32: 0.85 | F32: =3600/D32*C32*E32 -> 204 | G32: =5*48 -> 240 | H32: 2 | I32: 10.5 | J32: =I32*G32*F32*H32 -> 1028160 | K32: =$D$4 -> 800000 | L32: =J32-K32 -> 228160 | M32: =K32/J32 -> 0.77808901 | N32: Specific | O32: 50000000 | P32: 1 | Q32: =O32*P32 -> 50000000 | R32: =Q32/12/22/7/10.5/F32/2 -> 6.3156576 | S32: 5 | T32: 145 | U32: =S32*T32/F32 -> 3.5539216 | V32: =U32*K32 -> 2843137.3 | W32: 0 | X32: =24750*1.048*1.048*1.048 -> 28487.809 | Y32: =W32*X32/F32 -> 0
A33: #40 | B33: Bushing pressfit | C33: 1 | D33: 15 | E33: 0.85 | F33: =3600/D33*C33*E33 -> 204 | G33: =5*48 -> 240 | H33: 2 | I33: 10.5 | J33: =I33*G33*F33*H33 -> 1028160 | K33: =$D$4 -> 800000 | L33: =J33-K33 -> 228160 | M33: =K33/J33 -> 0.77808901 | N33: Specific | O33: 150000000 | P33: 1 | Q33: =O33*P33 -> 150000000 | R33: =Q33/12/22/7/10.5/F33/2 -> 18.946973 | S33: 5 | T33: 145 | U33: =S33*T33/F33 -> 3.5539216 | V33: =U33*K33 -> 2843137.3 | W33: 0 | X33: =24750*1.048*1.048*1.048 -> 28487.809 | Y33: =W33*X33/F33 -> 0
A34: #50 | B34: Inspection and packaging | C34: 1 | D34: 15 | E34: 0.85 | F34: =3600/D34*C34*E34 -> 204 | G34: =5*48 -> 240 | H34: 2 | I34: 10.5 | J34: =I34*G34*F34*H34 -> 1028160 | K34: =$D$4 -> 800000 | L34: =J34-K34 -> 228160 | M34: =K34/J34 -> 0.77808901 | N34: Specific | S34: 0 | U34: =S34*T34/F34 -> 0 | V34: =U34*K34 -> 0 | W34: 1 | X34: =24750*1.048*1.048*1.048 -> 28487.809 | Y34: =W34*X34/F34 -> 139.64612
I50: MES | J50: =MIN(J29:J49) -> 1028160 | O50: =SUM(Q29:Q49) -> 590000000 | Q50: Specific | R50: =SUMIF(N30:N49,Q50,R30:R49) -> 47.998998 | U50: =SUM(U29:U49) -> 31.985294 | V50: =SUM(V29:V49) -> 25588235 | Y50: =SUM(Y29:Y49) -> 139.64612 | Z50: =SUM(Z29:Z49) -> 0
Q51: Generic | R51: =SUMIF(N30:N49,Q51,R30:R49) -> 26.525762
A54: 항목 | C54: Y1 | D54: Y2 | E54: Y3 | F54: Y4 | G54: Y5 | H54: Y6 | I54: Y7 | J54: Y8 | K54: Y9 | L54: Y10 | M54: Y11 | N54: Y12
A55: Variables overhead
B56: Labor | C56: =Y50 -> 139.64612 | D56: =C56+(C56*$X$25) -> 146.34914 | E56: =D56+(D56*$X$25) -> 153.3739 | F56: =E56+(E56*$X$25) -> 160.73584 | G56: =F56+(F56*$X$25) -> 168.45116 | H56: =G56+(G56*$X$25) -> 176.53682 | I56: =H56+(H56*$X$25) -> 185.01059
B57: Electricity | C57: =U50 -> 31.985294 | D57: =C57 -> 31.985294 | E57: =D57 -> 31.985294 | F57: =E57 -> 31.985294 | G57: =F57 -> 31.985294 | H57: =G57 -> 31.985294 | I57: =H57 -> 31.985294
A58: Fixed overhead
B59: Indirect labor | C59: =C56*40% -> 55.858449 | D59: =D56*40% -> 58.539655 | E59: =E56*40% -> 61.349558 | F59: =F56*40% -> 64.294337 | G59: =G56*40% -> 67.380465 | H59: =H56*40% -> 70.614728 | I59: =I56*40% -> 74.004235
B60: Repairing | C60: =($R$50+$R$51)*10% -> 7.4524759 | D60: =($R$50+$R$51)*10% -> 7.4524759 | E60: =($R$50+$R$51)*10% -> 7.4524759 | F60: =($R$50+$R$51)*10% -> 7.4524759 | G60: =($R$50+$R$51)*10% -> 7.4524759 | H60: =($R$50+$R$51)*10% -> 7.4524759 | I60: =($R$50+$R$51)*10% -> 7.4524759
B61: Indirect overhead | C61: =(C60+C57+C62+C63)*40% -> 45.585012 | D61: =(D60+D57+D62+D63)*40% -> 45.585012 | E61: =(E60+E57+E62+E63)*40% -> 45.585012 | F61: =(F60+F57+F62+F63)*40% -> 45.585012 | G61: =(G60+G57+G62+G63)*40% -> 45.585012 | H61: =(H60+H57+H62+H63)*40% -> 45.585012 | I61: =(I60+I57+I62+I63)*40% -> 45.585012
B62: Armotization (범용) | C62: =$R$51 -> 26.525762 | D62: =C62 -> 26.525762 | E62: =D62 -> 26.525762 | F62: =E62 -> 26.525762 | G62: =F62 -> 26.525762 | H62: =G62 -> 26.525762 | I62: =H62 -> 26.525762
B63: Armotization (전용) | C63: =$R$50 -> 47.998998 | D63: =C63 -> 47.998998 | E63: =D63 -> 47.998998 | F63: =E63 -> 47.998998 | G63: =F63 -> 47.998998 | H63: =G63 -> 47.998998 | I63: =H63 -> 47.998998
A66: 항목 | C66: Y1 | D66: Y2 | E66: Y3 | F66: Y4 | G66: Y5 | H66: Y6 | I66: Y7
A67: SG&A | C67: =SUM(C56:C63)*25% -> 88.763028 | D67: =SUM(D56:D63)*25% -> 91.109083 | E67: =SUM(E56:E63)*25% -> 93.567749 | F67: =SUM(F56:F63)*25% -> 96.14443 | G67: =SUM(G56:G63)*25% -> 98.844792 | H67: =SUM(H56:H63)*25% -> 101.67477 | I67: =SUM(I56:I63)*25% -> 104.64059

Sheet COVER
A2: Business Case Study
D6: Program | F6: ='Commercial Input'!C6 -> Connector housing ass
D8: Contents
E9: A. Program info / ROI summary
F11: 1. Business projection based on quotation
F12: 2. NPV/IRR/PAYBACK
F13: 3. Review
A15: ='Commercial Input'!C5 -> 46033
A17: 작성자 : 박영상 부장

Sheet Program info Study summary
A2: A. Program info / Study summary
A5: 1. Program info
A6: Customer | B6: ='Commercial Input'!C7 -> SK | D6: Part Name | E6: ='Commercial Input'!C8 -> Connector housing ass | G6: Part Number | H6: ='Commercial Input'!C9 -> TBD | J6: OEM/Model | K6: ='Commercial Input'!C10 -> 0
A8: Target Price | B8: ='Commercial Input'!C11 -> 0 | D8: SOP | E8: ='Commercial Input'!C12 -> 2028
A10: 2. Business projection based on quotation
A11: Total sales | B11: =SUM(C18:M18) -> 6720000000 | C11: KRW
A12: Year | C12: SOP | D12: Year 2 | E12: Year 3 | F12: Year 4 | G12: Year 5 | H12: Year 6 | I12: Year 7 | J12: Year 8 | K12: Year 9 | L12: Year 10 | M12: Year 11
A13: Volume | C13: ='Commercial Input'!C14 -> 800000 | D13: ='Commercial Input'!D14 -> 800000 | E13: ='Commercial Input'!E14 -> 800000 | F13: ='Commercial Input'!F14 -> 800000 | G13: ='Commercial Input'!G14 -> 800000 | H13: ='Commercial Input'!H14 -> 800000 | I13: ='Commercial Input'!I14 -> 800000 | J13: ='Commercial Input'!J14 -> 0 | ... M13: ='Commercial Input'!M14 -> 0
A14: Quoted Price (KRW) | C14: ='Commercial Input'!C17 -> 1200 | D14: ='Commercial Input'!D17 -> 1200 | E14: ='Commercial Input'!E17 -> 1200 | F14: ='Commercial Input'!F17 -> 1200 | G14: ='Commercial Input'!G17 -> 1200 | H14: ='Commercial Input'!H17 -> 1200 | I14: ='Commercial Input'!I17 -> 1200 | J14: ='Commercial Input'!J17 -> 0 | ... M14: ='Commercial Input'!M17 -> 0
A15: Contribution margin | C15: ='AP 3. ROI review'!E47 -> 0.45430715 | D15: ='AP 3. ROI review'!F47 -> 0.44872131 | E15: ='AP 3. ROI review'!G47 -> 0.44286734 | F15: ='AP 3. ROI review'!H47 -> 0.43673239 | G15: ='AP 3. ROI review'!I47 -> 0.43030295 | H15: ='AP 3. ROI review'!J47 -> 0.42356491 | I15: ='AP 3. ROI review'!K47 -> 0.41650343 | J15: ='AP 3. ROI review'!L47 -> #DIV/0! | ... M15: ='AP 3. ROI review'!O47 -> #DIV/0!
A16: BEP Unit | C16: ='AP 3. ROI review'!E50 -> 490231.08 | D16: ='AP 3. ROI review'!F50 -> 504938.76 | E16: ='AP 3. ROI review'!G50 -> 520750.56 | F16: ='AP 3. ROI review'!H50 -> 537776.22 | G16: ='AP 3. ROI review'!I50 -> 556140.1 | H16: ='AP 3. ROI review'!J50 -> 575983.73 | I16: ='AP 3. ROI review'!K50 -> 428831.38 | J16: ='AP 3. ROI review'!L50 -> #DIV/0! | ... M16: ='AP 3. ROI review'!O50 -> #DIV/0!
A17: Annual Volume VS BEP Unit | C17: =C13-C16 -> 309768.92 | D17: =D13-D16 -> 295061.24 | E17: =E13-E16 -> 279249.44 | F17: =F13-F16 -> 262223.78 | G17: =G13-G16 -> 243859.9 | H17: =H13-H16 -> 224016.27 | I17: =I13-I16 -> 371168.62 | J17: =J13-J16 -> #DIV/0! | ... M17: =M13-M16 -> #DIV/0!
A18: Sales | C18: =(C13*C14) -> 960000000 | D18: =(D13*D14) -> 960000000 | E18: =(E13*E14) -> 960000000 | F18: =(F13*F14) -> 960000000 | G18: =(G13*G14) -> 960000000 | H18: =(H13*H14) -> 960000000 | I18: =(I13*I14) -> 960000000 | J18: =(J13*J14) -> 0 | ... M18: =(M13*M14) -> 0 | O18: =SUM(C18:M18) -> 6720000000
A19: Expected EBIT (Mil KRW) | C19: ='AP 3. ROI review'!E33*1000000 -> 2.4948028e+08 | D19: ='AP 3. ROI review'!F33*1000000 -> 98880319 | E19: ='AP 3. ROI review'!G33*1000000 -> 1.4840455e+08 | F19: ='AP 3. ROI review'!H33*1000000 -> 1.3742594e+08 | G19: ='AP 3. ROI review'!I33*1000000 -> 65920363 | H19: ='AP 3. ROI review'!J33*1000000 -> 1.1386252e+08 | I19: ='AP 3. ROI review'!K33*1000000 -> 1.8551161e+08 | J19: ='AP 3. ROI review'!L33*1000000 -> 0 | ... M19: ='AP 3. ROI review'!O33*1000000 -> 0 | O19: =SUM(C19:M19) -> 9.9948558e+08
A20: OP | C20: ='AP 3. ROI review'!E52 -> 0.17591279 | D20: ='AP 3. ROI review'!F52 -> 0.16550033 | E20: ='AP 3. ROI review'!G52 -> 0.15458807 | F20: ='AP 3. ROI review'!H52 -> 0.14315202 | G20: ='AP 3. ROI review'!I52 -> 0.13116705 | H20: ='AP 3. ROI review'!J52 -> 0.11860679 | I20: ='AP 3. ROI review'!K52 -> 0.19324126 | J20: ='AP 3. ROI review'!L52 -> #DIV/0! | ... M20: ='AP 3. ROI review'!O52 -> #DIV/0! | O20: =O19/O18 -> 0.14873297
A21: Annual Cost savings to customer | D21: =((C14-D14)*D13) -> 0 | E21: =((D14-E14)*E13) -> 0 | F21: =((E14-F14)*F13) -> 0 | G21: =((F14-G14)*G13) -> 0 | H21: =((G14-H14)*H13) -> 0 | I21: =((H14-I14)*I13) -> 0
A22: Annual Cost savings rate | D22: =D21/D18 -> 0 | E22: =E21/E18 -> 0 | F22: =F21/F18 -> 0 | G22: =G21/G18 -> 0 | H22: =H21/H18 -> 0 | I22: =I21/I18 -> 0
A23: Annual Cost savings Accumulated | D23: =D21 -> 0 | E23: =D23+E21 -> 0 | F23: =E23+F21 -> 0 | G23: =F23+G21 -> 0 | H23: =G23+H21 -> 0 | I23: =H23+I21 -> 0
A26: B. Return
A28: NPV/IRR | B28: ='AP 3. ROI review'!G96 -> 343.4026 | C28: 백만원 | H28: Payback time | I28: ='AP 3. ROI review'!A112 -> 2.0113427 | J28: Years
A47: A. Program info / Study summary
A51: C. OPINION

Sheet AP 1. Assumption
A2: Appendix 1. Assumption
A5: 1. FX rate | B5: ='Commercial Input'!C18 -> 0 | C5: 환율 연동 안될시 혹은 불확실할 경우 변동성 리스크 베타 반영
A6: 2. Annual price reduction | C6: ='Commercial Input'!C19 -> 0
A8: 3. Net working capital
A9: Div. | B9: Material | C9: Work in process | D9: Finished parts | E9: Payment terms Days | F9: Payable terms
A10: Applied (Days) | B10: 30 | C10: 7 | D10: 7 | E10: ='Commercial Input'!C41 -> 60 | F10: ='Commercial Input'!E41 -> 23.676804
A11: Turnover | B11: =264/B10 -> 8.8 | C11: =264/C10 -> 37.714286 | D11: =264/D10 -> 37.714286 | E11: =360/E10 -> 6 | F11: =360/F10 -> 15.204755
C13: (90일 표준으로 요구 증가) | D13: (연 매출 / 연 재고자산) | E13: (연 매출원가 / 연 매입채무)
A14: 4. Risk free return rate | C14: ='Commercial Input'!C23 -> 0.04069 | D14: 회사채수익률(3년,AA-) ('22.09.07) | F14: http://ecos.bok.or.kr/jsp/vis/keystat/#/key
A15: 5. Interest Rate for Bank Borrowings | C15: ='Commercial Input'!C24 -> 0.06 | D15: 신라 재무팀 정보 | F15: 한국은행 경제 통계시스템
A16: 6. Income Taxes | C16: ='Commercial Input'!C25 -> 0.22 | D16: 신라 재무팀 정보
A17: 7. Fixed costs increase | C17: ='Commercial Input'!C28 -> 0.02
A18: 8. Investment | C18: ='Commercial Input'!C20 -> 590000000
A19: 9. Business link | C19: ='Commercial Input'!C21 -> 0
A20: 10. Tooling costs | C20: ='Commercial Input'!C22 -> 80604000

Sheet AP 2. Discount rate
A2: 2. Appendix Discount rate
A5: Cost of equity capital(CAPM model) | F5: Cost of equity capital(Shilla's experience)
A6: rf corporate bond 3 yeas AA- in Korea | C6: ='Commercial Input'!C23 -> 0.04069 | D6: (회사채수익률(3년,AA-))
A7: Risk premium [E(rm)-rf] | C7: ='Commercial Input'!C26-'AP 2. Discount rate'!C6 -> 0.05931 | D7: (2022 자본시장 기대 수익률 12% CNBC - 무위험 수익률)
A8: Beta | C8: =F27 -> 1.1593813 | D8: (글로벌 경제 상황 변동에 따른 변동성)
A9: rf+[E(rm)-rf] X B | C9: =C6+C8*C7 -> 0.10945291 | D9: (이론상 주주요구 수익률) | F9: Shilla ROE | G9: ='Commercial Input'!K38 -> 0.23278864 | H9: (신라공업 ROE)
A10: (+) Korean Equity risk premium | C10: ='Commercial Input'!C27 -> 0.0679 | D10: (한국 자본 시장 리스크 프리미엄) | H10: Avg 2016~2022
A11: Cost of Capital | C11: =MAX($C$9,$G$9)+C10 -> 0.30068864 | D11: (Bigger one between theoretical Cost VS Shilla ROE, + Korean Equity risk premium)
A12: Financial liability costs | C12: 0.06 | D12: (금융 비용 - 장기 차입금 이자율)
A13: WACC | C13: =((C12*C20)*(1-'AP 1. Assumption'!C16))+(C11*C21) -> 0.14786538
A14: (+) FX rate risk | C14: ='FX Rate 변동성 '!AE10 -> 0.021881049 | D14: (환율 변동성에 대한 프리미엄 : 2021.1 ~ 월평균 환율 변동의 표준편차)
A15: Internally required rate | C15: =C13+C14 -> 0.16974643 | D15: (최소 요구 수익률)
D17: 베타 분석 (기준업체 우리산업 - As of May 10th 2023)
D18: Find the unlevered beta
A19: 2022년 재무상태표 기준 자본 부채 비율 | D19: Current beta of the company = | F19: ='Commercial Input'!C29 -> 1.28 | G19: KOSDAQ
A20: Weighted ratio of borrowings | C20: =B25/B24 -> 0.60193028 | D20: Marginal tax rate for the company = | F20: ='Commercial Input'!C30 -> 0.21
A21: Weighted ratio of equity | C21: =B26/B24 -> 0.39806972 | D21: The debt/equity ratio | F21: ='Commercial Input'!C31 -> 1.78
D22: Unlevered Beta for the firm = | F22: =F19/(1+(1-F20)*(F21)) -> 0.53195911 | G22: B / ((1+Tax) X Debt/Equity ratio)
D23: Find the levered beta
A24: 2022 Asset | B24: ='Commercial Input'!C32 -> 114515457295 | D24: The unlevered beta of the company = | F24: =F22 -> 0.53195911 | G24: Unleveraged beta
A25: 2022 Borrowings | B25: ='Commercial Input'!C33 -> 68930320933 | C25: =B25/B26 -> 1.5121227 | D25: Marginal tax rate for the company = | F25: ='Commercial Input'!C25 -> 0.22 | G25: 신라 법인세율
A26: 2022 capital | B26: ='Commercial Input'!C34 -> 45585136362 | D26: The debt/equity ratio | F26: =B25/B26 -> 1.5121227 | G26: 신라 부채비율
D27: Levered Beta for the firm = | F27: =F24*(1+(1-F25)*(F26)) -> 1.1593813 | G27: Unleveraged B X (1+(1-Tax) X Debt/Equity ratio)

Sheet AP 3. ROI review
A2: Appendix 3. ROI review
A5: Case 1 : 현재 견적 기준
A6: 1. Income statement (Sales and profit projection)
A7: Assumption | P7: Mil KRW
A8: Year | C8: SOP -2 year | D8: SOP -1 year | E8: SOP Year | F8: 2nd year | G8: 3rd year | H8: 4th year | I8: 5th year | J8: 6th year | K8: 7th year | L8: 8th year | M8: 9th year | N8: 10th year | O8: 11th year | P8: 12th year
A9: MES | E9: ='Commercial Input'!C15 -> 1028160 | F9: ='Commercial Input'!D15 -> 1028160 | G9: ='Commercial Input'!E15 -> 1028160 | H9: ='Commercial Input'!F15 -> 1028160 | I9: ='Commercial Input'!G15 -> 1028160 | J9: ='Commercial Input'!H15 -> 1028160 | K9: ='Commercial Input'!I15 -> 1028160
A10: Sales Volume | E10: ='Commercial Input'!C14 -> 800000 | F10: ='Commercial Input'!D14 -> 800000 | G10: ='Commercial Input'!E14 -> 800000 | H10: ='Commercial Input'!F14 -> 800000 | I10: ='Commercial Input'!G14 -> 800000 | J10: ='Commercial Input'!H14 -> 800000 | K10: ='Commercial Input'!I14 -> 800000
A11: Quoted price | E11: ='Commercial Input'!C17 -> 1200 | F11: ='Commercial Input'!D17 -> 1200 | G11: ='Commercial Input'!E17 -> 1200 | H11: ='Commercial Input'!F17 -> 1200 | I11: ='Commercial Input'!G17 -> 1200 | J11: ='Commercial Input'!H17 -> 1200 | K11: ='Commercial Input'!I17 -> 1200
A12: Revenue | D12: 0 | E12: =(E11*E10)/1000000 -> 960 | F12: =(F11*F10)/1000000 -> 960 | G12: =(G11*G10)/1000000 -> 960 | H12: =(H11*H10)/1000000 -> 960 | I12: =(I11*I10)/1000000 -> 960 | J12: =(J11*J10)/1000000 -> 960 | K12: =(K11*K10)/1000000 -> 960 | L12: =(L11*L10)/1000000 -> 0 | ... P12: =(P11*P10)/1000000 -> 0
A13: (-) Variables overhead | B13: % of price | D13: =(D14+D16+D17+D18+D19+D15)*D10/1000000 -> 0 | E13: =(E14+E16+E17+E18+E19+E15+E20)*E10/1000000 -> 523.86513 | F13: =(F14+F16+F17+F18+F19+F15+F20)*F10/1000000 -> 529.22755 | G13: =(G14+G16+G17+G18+G19+G15+G20)*G10/1000000 -> 534.84735 | H13: =(H14+H16+H17+H18+H19+H15+H20)*H10/1000000 -> 540.73691 | I13: =(I14+I16+I17+I18+I19+I15+I20)*I10/1000000 -> 546.90917 | J13: =(J14+J16+J17+J18+J19+J15+J20)*J10/1000000 -> 553.37769 | K13: =(K14+K16+K17+K18+K19+K15+K20)*K10/1000000 -> 560.1567 | L13: =(L14+L16+L17+L18+L19+L15+L20)*L10/1000000 -> 0 | ... P13: =(P14+P16+P17+P18+P19+P15+P20)*P10/1000000 -> 0
A14: Material | B14: =E14/$E$11 -> 0.36666667 | E14: ='Materials input'!P40 -> 440 | F14: ='Materials input'!R40 -> 440 | G14: ='Materials input'!T40 -> 440 | H14: ='Materials input'!V40 -> 440 | I14: ='Materials input'!X40 -> 440 | J14: ='Materials input'!Z40 -> 440 | K14: ='Materials input'!AB40 -> 440 | L14: ='Materials input'!AD40 -> 0 | M14: ='Materials input'!AF40 -> 0
A15: Material Control | B15: =E15/$E$11 -> 0.011 | E15: ='AP 3. ROI review'!E14*3% -> 13.2 | F15: =F14*3% -> 13.2 | G15: =G14*3% -> 13.2 | H15: =H14*3% -> 13.2 | I15: =I14*3% -> 13.2 | J15: =J14*3% -> 13.2 | K15: =K14*3% -> 13.2 | L15: =L14*3% -> 0 | M15: =M14*3% -> 0
A16: Labor | B16: =E16/$E$11 -> 0.11637177 | E16: ='Process input'!C56 -> 139.64612 | F16: ='Process input'!D56 -> 146.34914 | G16: ='Process input'!E56 -> 153.3739 | H16: ='Process input'!F56 -> 160.73584 | I16: ='Process input'!G56 -> 168.45116 | J16: ='Process input'!H56 -> 176.53682 | K16: ='Process input'!I56 -> 185.01059 | L16: ='Process input'!J56 -> 0 | ... O16: ='Process input'!M56 -> 0
A17: Electricity | B17: =E17/$E$11 -> 0.026654412 | E17: ='Process input'!C57 -> 31.985294 | F17: ='Process input'!D57 -> 31.985294 | G17: ='Process input'!E57 -> 31.985294 | H17: ='Process input'!F57 -> 31.985294 | I17: ='Process input'!G57 -> 31.985294 | J17: ='Process input'!H57 -> 31.985294 | K17: ='Process input'!I57 -> 31.985294 | L17: ='Process input'!J57 -> 0 | ... O17: ='Process input'!M57 -> 0
A18: Packaging | B18: =E18/$E$11 -> 0.0125 | E18: ='Materials input'!P42 -> 15 | F18: ='Materials input'!R42 -> 15 | G18: ='Materials input'!T42 -> 15 | H18: ='Materials input'!V42 -> 15 | I18: ='Materials input'!X42 -> 15 | J18: ='Materials input'!Z42 -> 15 | K18: ='Materials input'!AB42 -> 15 | L18: ='Materials input'!AD42 -> 0 | M18: ='Materials input'!AF42 -> 0
A19: Logistics | B19: =E19/$E$11 -> 0.0125 | E19: ='Materials input'!P43 -> 15 | F19: ='Materials input'!R43 -> 15 | G19: ='Materials input'!T43 -> 15 | H19: ='Materials input'!V43 -> 15 | I19: ='Materials input'!X43 -> 15 | J19: ='Materials input'!Z43 -> 15 | K19: ='Materials input'!AB43 -> 15 | L19: ='Materials input'!AD43 -> 0 | M19: ='Materials input'!AF43 -> 0
A21: (-) Fixed overhead | D21: =((D22+D23+D24)*D9)/1000000 -> 0 | E21: =((E22+E23+E24)*E9)/1000000 -> 111.96245 | F21: =((F22+F23+F24)*F9)/1000000 -> 114.71915 | G21: =((G22+G23+G24)*G9)/1000000 -> 117.60819 | H21: =((H22+H23+H24)*H9)/1000000 -> 120.63589 | I21: =((I22+I23+I24)*I9)/1000000 -> 123.80892 | J21: =((J22+J23+J24)*J9)/1000000 -> 127.13426 | K21: =((K22+K23+K24)*K9)/1000000 -> 130.61922 | ... P21: =((P22+P23+P24)*P9)/1000000 -> 0
A22: Indirect labor | B22: =E22/$E$11 -> 0.046548708 | E22: ='Process input'!C59 -> 55.858449 | F22: ='Process input'!D59 -> 58.539655 | G22: ='Process input'!E59 -> 61.349558 | H22: ='Process input'!F59 -> 64.294337 | I22: ='Process input'!G59 -> 67.380465 | J22: ='Process input'!H59 -> 70.614728 | K22: ='Process input'!I59 -> 74.004235 | L22: ='Process input'!J59 -> 0 | ... O22: ='Process input'!M59 -> 0
A23: Repairing | B23: =E23/$E$11 -> 0.0062103966 | E23: ='Process input'!C60 -> 7.4524759 | F23: ='Process input'!D60 -> 7.4524759 | G23: ='Process input'!E60 -> 7.4524759 | H23: ='Process input'!F60 -> 7.4524759 | I23: ='Process input'!G60 -> 7.4524759 | J23: ='Process input'!H60 -> 7.4524759 | K23: ='Process input'!I60 -> 7.4524759 | L23: ='Process input'!J60 -> 0 | ... O23: ='Process input'!M60 -> 0
A24: Indirect overhead | B24: =E24/$E$11 -> 0.03798751 | E24: ='Process input'!C61 -> 45.585012 | F24: ='Process input'!D61 -> 45.585012 | G24: ='Process input'!E61 -> 45.585012 | H24: ='Process input'!F61 -> 45.585012 | I24: ='Process input'!G61 -> 45.585012 | J24: ='Process input'!H61 -> 45.585012 | K24: ='Process input'!I61 -> 45.585012 | L24: ='Process input'!J61 -> 0 | ... O24: ='Process input'!M61 -> 0
A25: (-)SG&A | E25: ='Process input'!C67*E10/1000000 -> 71.010423 | F25: ='Process input'!D67*F10/1000000 -> 72.887267 | G25: ='Process input'!E67*G10/1000000 -> 74.854199 | H25: ='Process input'!F67*H10/1000000 -> 76.915544 | I25: ='Process input'!G67*I10/1000000 -> 79.075834 | J25: ='Process input'!H67*J10/1000000 -> 81.339818 | K25: ='Process input'!I67*K10/1000000 -> 83.712472 | L25: ='Process input'!J67*L10/1000000 -> 0 | ... O25: ='Process input'!M67*O10/1000000 -> 0 | V25: =E11-E14-E15-E16-E17-E18-E19-E22-E23-E24-E25 -> 365.26222 | W25: =V25/E11 -> 0.30438519
A26: (-)Commission | L26: =(59*L10)/1000000 -> 0 | M26: =(59*M10)/1000000 -> 0
A27: (-) Depreciation (7 years) | D27: =D78 -> 84.285714 | E27: =E78 -> 84.285714 | F27: =F78 -> 84.285714 | G27: =G78 -> 84.285714 | H27: =H78 -> 84.285714 | I27: =I78 -> 84.285714 | J27: =J78 -> 84.285714 | K27: =K78 -> 0 | ... P27: =P78 -> 0
A28: (-) R&D | D28: ='Commercial Input'!E20/1000000 -> 0
A29: EBIT | D29: =D12-D13-D21-D25-D27-D28-D26 -> -84.285714 | E29: =E12-E13-E21-E25-E27-E28-E26 -> 168.87628 | F29: =F12-F13-F21-F25-F27-F28-F26 -> 158.88032 | G29: =G12-G13-G21-G25-G27-G28-G26 -> 148.40455 | H29: =H12-H13-H21-H25-H27-H28-H26 -> 137.42594 | I29: =I12-I13-I21-I25-I27-I28-I26 -> 125.92036 | J29: =J12-J13-J21-J25-J27-J28-J26 -> 113.86252 | K29: =K12-K13-K21-K25-K27-K28-K26 -> 185.51161 | ... P29: =P12-P13-P21-P25-P27-P28-P26 -> 0
A30: (-) Tooling Purchasing | D30: =D89 -> 67.2 | E30: =E89 -> 0 | F30: =F89 -> 60 | G30: =G89 -> 0 | H30: =H89 -> 0 | I30: =I89 -> 60 | J30: =J89 -> 0 | K30: =K89 -> 0 | ... P30: =P89 -> 0
A31: (+) Tooling Sales | E31: ='Commercial Input'!C22/1000000 -> 80.604
A32: Non-operational profit | D32: =D31-D30 -> -67.2 | E32: =E31-E30 -> 80.604 | F32: =F31-F30 -> -60 | G32: =G31-G30 -> 0 | H32: =H31-H30 -> 0 | I32: =I31-I30 -> -60 | J32: =J31-J30 -> 0 | K32: =K31-K30 -> 0 | ... P32: =P31-P30 -> 0
A33: Operational + Non-operational profit | D33: =D29+D32 -> -151.48571 | E33: =E29+E32 -> 249.48028 | F33: =F29+F32 -> 98.880319 | G33: =G29+G32 -> 148.40455 | H33: =H29+H32 -> 137.42594 | I33: =I29+I32 -> 65.920363 | J33: =J29+J32 -> 113.86252 | K33: =K29+K32 -> 185.51161 | ... P33: =P29+P32 -> 0
A34: Operation profit(1) | D34: =D33/D12 -> #DIV/0! | E34: =E33/E12 -> 0.25987529 | F34: =F33/F12 -> 0.10300033 | G34: =G33/G12 -> 0.15458807 | H34: =H33/H12 -> 0.14315202 | I34: =I33/I12 -> 0.068667045 | J34: =J33/J12 -> 0.11860679 | K34: =K33/K12 -> 0.19324126 | ... P34: =P33/P12 -> #DIV/0!
A35: EBITDA | D35: =D33+D27 -> -67.2 | E35: =E33+E27 -> 333.766 | F35: =F33+F27 -> 183.16603 | G35: =G33+G27 -> 232.69026 | H35: =H33+H27 -> 221.71166 | I35: =I33+I27 -> 150.20608 | J35: =J33+J27 -> 198.14823 | K35: =K33+K27 -> 185.51161 | ... P35: =P33+P27 -> 0
A36: Operation profit(2) | D36: =D35/D12 -> #DIV/0! | E36: =E35/E12 -> 0.34767291 | F36: =F35/F12 -> 0.19079795 | G36: =G35/G12 -> 0.24238569 | H36: =H35/H12 -> 0.23094964 | I36: =I35/I12 -> 0.15646466 | J36: =J35/J12 -> 0.20640441 | K36: =K35/K12 -> 0.19324126 | ... P36: =P35/P12 -> #DIV/0!
A37: Tax | D37: =D81 -> -33.326857 | E37: =E81 -> 54.885662 | F37: =F81 -> 21.75367 | G37: =G81 -> 32.649001 | H37: =H81 -> 30.233707 | I37: =I81 -> 14.50248 | J37: =J81 -> 25.049753 | K37: =K81 -> 40.812553 | ... P37: =P81 -> 0
A38: Net profit | D38: =D33-D37 -> -118.15886 | E38: =E33-E37 -> 194.59462 | F38: =F33-F37 -> 77.126649 | G38: =G33-G37 -> 115.75555 | H38: =H33-H37 -> 107.19224 | I38: =I33-I37 -> 51.417883 | J38: =J33-J37 -> 88.812762 | K38: =K33-K37 -> 144.69905 | ... P38: =P33-P37 -> 0
A40: Appendix 3. ROI review
A42: BEP Review
A43: Year | D43: SOP -1 year | E43: SOP Year | F43: 2nd year | G43: 3rd year | H43: 4th year | I43: 5th year | J43: 6th year | K43: 7th year | L43: 8th year | M43: 9th year | N43: 10th year | O43: 11th year | P43: 12th year
A44: Unit part | E44: =E11 -> 1200 | F44: =F11 -> 1200 | G44: =G11 -> 1200 | H44: =H11 -> 1200 | I44: =I11 -> 1200 | J44: =J11 -> 1200 | K44: =K11 -> 1200 | L44: =L11 -> 0 | ... P44: =P11 -> 0
A45: Variable per unit | E45: =E14+E15+E16+E17+E18+E19 -> 654.83142 | F45: =F14+F15+F16+F17+F18+F19 -> 661.53443 | G45: =G14+G15+G16+G17+G18+G19 -> 668.55919 | H45: =H14+H15+H16+H17+H18+H19 -> 675.92114 | I45: =I14+I15+I16+I17+I18+I19 -> 683.63646 | J45: =J14+J15+J16+J17+J18+J19 -> 691.72211 | K45: =K14+K15+K16+K17+K18+K19 -> 700.19588 | L45: =L14+L15+L16+L17+L18+L19 -> 0 | ... P45: =P14+P15+P16+P17+P18+P19 -> 0
A46: Contribution margin | E46: =E44-E45 -> 545.16858 | F46: =F44-F45 -> 538.46557 | G46: =G44-G45 -> 531.44081 | H46: =H44-H45 -> 524.07886 | I46: =I44-I45 -> 516.36354 | J46: =J44-J45 -> 508.27789 | K46: =K44-K45 -> 499.80412 | L46: =L44-L45 -> 0 | ... P46: =P44-P45 -> 0
...

Sheet 5. 위험성 평가
A1: Risks assessment and countermeasures
A3: 구분 | B3: 위험요소 | C3: 발생할 수 있는 영향 | D3: 시나리오 검토 | E3: 민감도 (현재 ->) | F3: 위험도 | G3: 협업부서 | H3: 위험 대응 및 모리터링 방안
A4: 거시적 환경 변화 | B4: 금리 인상 | C4: 금리 인상에 따른 자본비용 증가 | D4: 시장금리 1% 상승
D5: 시장금리 2% 상승
B6: 환율 하락 | C6: 환율 하락에 따른 이익 감소 | D6: +/-100 제시 (최소)
B7: 경기 침체 | C7: OEM 자동차 생산량 대폭 감소 | D7: 물량 30% 감소
D8: 물량 50% 감소
A9: 시장경쟁 심화 | B9: 신규 경쟁기업진입 | C9: 저가격 경쟁사에 따른 중도 리소싱 | D9: 3년차 프로그램 종료
B10: 고객 가격인하 압박 | C10: 고객 가격 인하 요구 | D10: 가격 5% 인하 요구시
D11: 가격 10% 인하 요구시
A12: 생산요소 변동 | B12: 자재비 인상 | C12: 협력업체 가격인상 요구(연동 제외) | D12: 자재비 전체적 10% 인상시
B13: 생산효율 저하 | C13: 효율 저하에 따른 원가 인상 | D13: 견적기준 85% -> 80%
A14: 기타 | B14: 고객 기술 변화 | C14: 프로그램 조기 종료 | D14: 4년차 프로그램 종료
B15: 환경규제 | C15: 고객이 ESG 요구 강화 | D15: 프로그램 탄소 배출량 요구

Sheet FX Rate 변동성 
A1: FX rate variance
A3: Div | B3: 44197 | C3: 44228 | D3: 44256 | E3: 44287 | F3: 44317 | G3: 44348 | H3: 44378 | I3: 44409 | J3: 44440 | K3: 44470 | L3: 44501 | M3: 44531 | N3: 44562 | O3: 44593 | P3: 44621 | Q3: 44652 | R3: 44682 | S3: 44713 | T3: 44743 | U3: 44774 | V3: 44805 | W3: 44835 | X3: 44866 | Y3: 44896 | Z3: 44927 | AA3: 44958 | AB3: 44986 | AC3: 45017 | AG3: Max | AH3: Min | AI3: 평균 | AK3: 표준 편차
A4: KRW / USD | B4: 1097.49 | C4: 1111.72 | D4: 1131.02 | E4: 1119.4 | F4: 1123.28 | G4: 1121.3 | H4: 1143.98 | I4: 1160.34 | J4: 1169.54 | K4: 1182.82 | L4: 1182.91 | M4: 1183.7 | N4: 1194.01 | O4: 1198.34 | P4: 1221.03 | Q4: 1232.34 | R4: 1269.88 | S4: 1277.35 | T4: 1307.4 | U4: 1318.44 | V4: 1391.59 | W4: 1426.66 | X4: 1364.1 | Y4: 1296.22 | Z4: 1247.25 | AA4: 1270.74 | AB4: 1305.73 | AC4: 1320.01 | AG4: =MAX(B4:AC4) -> 1426.66 | AH4: =MIN(B4:AC4) -> 1097.49 | AI4: =AVERAGE(B4:AC4) -> 1227.4496 | AK4: =_xlfn.STDEV.P(B4:X4) -> 92.406956 | AL4: =AK4/AI4 -> 0.075283704 | AM4: =_xlfn.VAR.S(B4:X4) -> 8927.1839
A5: KRW / RMB | B5: 169.61 | C5: 172.34 | D5: 173.76 | E5: 171.44 | F5: 174.55 | G5: 174.66 | H5: 176.6 | I5: 179.13 | J5: 181.18 | K5: 184.06 | L5: 185.11 | M5: 185.74 | N5: 187.75 | O5: 188.81 | P5: 192.16 | Q5: 191.82 | R5: 188.78 | S5: 190.68 | T5: 194.13 | U5: 193.75 | V5: 198.19 | W5: 198.37 | X5: 189.53 | Y5: 185.47 | Z5: 183.16 | AA5: 185.97 | AB5: 189.1 | AC5: 191.6 | AG5: =MAX(B5:AC5) -> 198.37 | AH5: =MIN(B5:AC5) -> 169.61 | AI5: =AVERAGE(B5:AC5) -> 184.90893 | AK5: =_xlfn.STDEV.P(B5:X5) -> 8.690102 | AL5: =AK5/AI5 -> 0.04699666 | AM5: =_xlfn.VAR.S(B5:M5) -> 31.08487
A6: KRW / EUR | B6: 1336.31 | C6: 1344.6 | D6: 1346.74 | E6: 1338.47 | F6: 1363.91 | G6: 1351.94 | H6: 1352.72 | I6: 1365.63 | J6: 1378.19 | K6: 1372.24 | L6: 1350.43 | M6: 1338.19 | N6: 1353.2 | O6: 1359.89 | P6: 1345.33 | Q6: 1334.08 | R6: 1342.43 | S6: 1348.96 | T6: 1332.91 | U6: 1334.53 | V6: 1377.09 | W6: 1404.83 | X6: 1388.29 | Y6: 1371.13 | Z6: 1342.37 | AA6: 1361.65 | AB6: 1398.5 | AC6: 1446.41 | AG6: =MAX(B6:AC6) -> 1446.41 | AH6: =MIN(B6:AC6) -> 1332.91 | AI6: =AVERAGE(B6:AC6) -> 1360.0346 | AK6: =_xlfn.STDEV.P(B6:X6) -> 18.512772
A7: KRW / JPY | B7: 1058.52 | C7: 1055.14 | D7: 1040.86 | E7: 1025.98 | F7: 1029.14 | G7: 1018.5 | H7: 1037.25 | I7: 1056.31 | J7: 1061.22 | K7: 1044.91 | L7: 1036.36 | M7: 1039.51 | N7: 1039.55 | O7: 1039.85 | P7: 1028.59 | Q7: 977.38 | R7: 985.49 | S7: 951.34 | T7: 955.93 | U7: 975.17 | V7: 973.2 | W7: 969.36 | X7: 956.51 | Y7: 959.12 | Z7: 956.76 | AA7: 956.68 | AB7: 977.31 | AC7: 990.52 | AG7: =MAX(B7:AC7) -> 1061.22 | AH7: =MIN(B7:AC7) -> 951.34 | AI7: =AVERAGE(B7:AC7) -> 1007.0164 | AK7: =_xlfn.STDEV.P(B7:X7) -> 36.630632
A9: Div | B9: 44197 | C9: 44228 | D9: 44256 | E9: 44287 | F9: 44317 | G9: 44348 | H9: 44378 | I9: 44409 | J9: 44440 | K9: 44470 | L9: 44501 | M9: 44531 | N9: 44562 | O9: 44593 | P9: 44621 | Q9: 44652 | R9: 44682 | S9: 44713 | T9: 44743 | U9: 44774 | V9: 44805 | W9: 44835 | X9: 44866 | Y9: 44896 | Z9: 44927 | AA9: 44958 | AB9: 44986 | AC9: 45017 | AD9: 분산 | AE9: 표준편차 | AG9: 변화량의 분산 | AI9: 표준 편차 | AL9: =_xlfn.VAR.S(C10:M10) -> 8.6665917e-05 | AM9: =AL10/AL9 -> 2.8698545 | AQ9: 달러 Slop | AR9: =SLOPE(C10:M10,C10:M10) -> 1
A10: KRW / USD | C10: =(C4-B4)/B4 -> 0.01296595 | D10: =(D4-C4)/C4 -> 0.017360486 | E10: =(E4-D4)/D4 -> -0.010273912 | F10: =(F4-E4)/E4 -> 0.0034661426 | G10: =(G4-F4)/F4 -> -0.001762695 | H10: =(H4-G4)/G4 -> 0.020226523 | I10: =(I4-H4)/H4 -> 0.014300949 | J10: =(J4-I4)/I4 -> 0.0079287106 | ... AC10: =(AC4-AB4)/AB4 -> 0.010936411 | AD10: =_xlfn.VAR.S(C10:AC10) -> 0.00049719495 | AE10: =_xlfn.STDEV.P(C10:AC10) -> 0.021881049 | AG10: =_xlfn.VAR.S(C10:AC10) -> 0.00049719495 | AI10: =_xlfn.STDEV.P(C10:AC10) -> 0.021881049 | AK10: 위엔화/달러의 상관관계 (공분산) | AL10: =_xlfn.COVARIANCE.S(C10:AC10,C11:AC11) -> 0.00024871857 | AQ10: 위엔화 Slop | AR10: =SLOPE(C11:M11,C10:M10) -> 0.71360205
A11: KRW / RMB | C11: =(C5-B5)/B5 -> 0.016095749 | D11: =(D5-C5)/C5 -> 0.0082395265 | E11: =(E5-D5)/D5 -> -0.01335175 | F11: =(F5-E5)/E5 -> 0.018140457 | G11: =(G5-F5)/F5 -> 0.00063019192 | H11: =(H5-G5)/G5 -> 0.011107294 | I11: =(I5-H5)/H5 -> 0.014326161 | J11: =(J5-I5)/I5 -> 0.011444203 | ... AC11: =(AC5-AB5)/AB5 -> 0.013220518 | AD11: =_xlfn.VAR.S(C11:AC11) -> 0.00023001226 | AE11: =_xlfn.STDEV.P(C11:AC11) -> 0.014882651 | AG11: =_xlfn.VAR.S(C11:AC11) -> 0.00023001226 | AI11: =_xlfn.STDEV.P(C11:AC11) -> 0.014882651 | AK11: 위엔화의 변동성 | AL11: =_xlfn.VAR.S(C11:AC11) -> 0.00023001226
A12: KRW / EUR | C12: =(C6-B6)/B6 -> 0.0062036504 | D12: =(D6-C6)/C6 -> 0.0015915514 | E12: =(E6-D6)/D6 -> -0.0061407547 | F12: =(F6-E6)/E6 -> 0.019006776 | G12: =(G6-F6)/F6 -> -0.0087762389 | H12: =(H6-G6)/G6 -> 0.00057694868 | I12: =(I6-H6)/H6 -> 0.0095437341 | J12: =(J6-I6)/I6 -> 0.0091972203 | ... AC12: =(AC6-AB6)/AB6 -> 0.034258134 | AD12: =_xlfn.VAR.S(C12:AC12) -> 0.00021554434 | AE12: =_xlfn.STDEV.P(C12:AC12) -> 0.014406985 | AG12: =_xlfn.VAR.S(C12:AC12) -> 0.00021554434 | AI12: =_xlfn.STDEV.P(C12:AC12) -> 0.014406985
A13: KRW / JPY | C13: =(C7-B7)/B7 -> -0.0031931376 | D13: =(D7-C7)/C7 -> -0.013533749 | E13: =(E7-D7)/D7 -> -0.014295871 | F13: =(F7-E7)/E7 -> 0.0030799821 | G13: =(G7-F7)/F7 -> -0.010338729 | H13: =(H7-G7)/G7 -> 0.018409426 | I13: =(I7-H7)/H7 -> 0.018375512 | J13: =(J7-I7)/I7 -> 0.0046482567 | ... AC13: =(AC7-AB7)/AB7 -> 0.013516694 | AD13: =_xlfn.VAR.S(C13:AC13) -> 0.00025108951 | AE13: =_xlfn.STDEV.P(C13:AC13) -> 0.015549595 | AG13: =_xlfn.VAR.S(C13:AC13) -> 0.00025108951 | AI13: =_xlfn.STDEV.P(C13:AC13) -> 0.015549595
AK15: 위엔화 표준편차 | AL15: =_xlfn.STDEV.P(C11:AC11) -> 0.014882651
AK16: 달러 표준 편차 | AL16: =_xlfn.STDEV.P(C10:AC10) -> 0.021881049

Sheet MES
C2: Quoting | D2: + K10 | E2: +K 20 | F2: +K 30 | G2: MES | H2: MES+10K
B3: Volume increase Sencario | C3: ='AP 3. ROI review'!E10 -> 800000 | D3: =C3+10000 -> 810000 | E3: =D3+10000 -> 820000 | F3: =E3+10000 -> 830000 | G3: ='AP 3. ROI review'!I9 -> 1028160 | H3: =G3+10000 -> 1038160
B4: Variable costs per unit | C4: ='AP 3. ROI review'!E45 -> 654.83142 | D4: =C4 -> 654.83142 | E4: =D4 -> 654.83142 | F4: =E4 -> 654.83142 | G4: =F4 -> 654.83142 | H4: =G4*1.02 -> 667.92805
B5: Annual total variable costs | C5: =C3*C4 -> 5.2386513e+08 | D5: =D3*D4 -> 5.3041345e+08 | E5: =E3*E4 -> 5.3696176e+08 | F5: =F3*F4 -> 5.4351008e+08 | G5: =G3*G4 -> 6.7327147e+08 | H5: =H3*H4 -> 6.9341618e+08
B6: Annual Fixed costs | C6: ='AP 3. ROI review'!E48*1000000 -> 2.6725858e+08 | D6: =C6 -> 2.6725858e+08 | E6: =D6 -> 2.6725858e+08 | F6: =E6 -> 2.6725858e+08 | G6: =F6 -> 2.6725858e+08 | H6: =G6 -> 2.6725858e+08
B7: Total costs | C7: =C5+C6 -> 7.9112372e+08 | D7: =D5+D6 -> 7.9767203e+08 | E7: =E5+E6 -> 8.0422035e+08 | F7: =F5+F6 -> 8.1076866e+08 | G7: =G5+G6 -> 9.4053005e+08 | H7: =H5+H6 -> 9.6067476e+08
B9: FAC | C9: =C6/C3 -> 334.07323 | D9: =D6/D3 -> 329.94887 | E9: =E6/E3 -> 325.9251 | F9: =F6/F3 -> 321.99829 | G9: =G6/G3 -> 259.93871
B10: Reduction strategy | D10: =C9-D9 -> 4.1243609 | E10: =D9-E9 -> 4.0237667 | F10: =E9-F9 -> 3.9268085 | G10: =F9-G9 -> 62.059584
B12: Unit price | C12: ='AP 3. ROI review'!E44 -> 1200 | D12: =C12 -> 1200 | E12: =D12 -> 1200 | F12: =E12 -> 1200 | G12: =F12 -> 1200 | H12: =G12 -> 1200
B13: Annual sales | C13: =C12*C3 -> 960000000 | D13: =D12*D3 -> 972000000 | E13: =E12*E3 -> 984000000 | F13: =F12*F3 -> 996000000 | G13: =G12*G3 -> 1233792000 | H13: =H12*H3 -> 1245792000
B15: AC | C15: =C7/C3 -> 988.90465 | D15: =D7/D3 -> 984.78029 | E15: =E7/E3 -> 980.75652 | F15: =F7/F3 -> 976.82971 | G15: =G7/G3 -> 914.77013 | H15: =H7/H3 -> 925.36291
B16: MR | D16: =(D13-C13)/(D3-C3) -> 1200 | E16: =(E13-D13)/(E3-D3) -> 1200 | F16: =(F13-E13)/(F3-E3) -> 1200 | G16: =(G13-F13)/(G3-F3) -> 1200 | H16: =(H13-G13)/(H3-G3) -> 1200
B17: MC | D17: =(D7-C7)/(D3-C3) -> 654.83142 | E17: =(E7-D7)/(E3-D3) -> 654.83142 | F17: =(F7-E7)/(F3-E3) -> 654.83142 | G17: =(G7-F7)/(G3-F3) -> 654.83142 | H17: =(H7-G7)/(H3-G3) -> 2014.471
F18: MES
F19: CT | G19: 60 | H19: Sec
F20: Efficiency | G20: 0.85 | H20: %
F21: Production / hour | G21: =3600/G19*G20 -> 51 | H21: Units
F22: Working hours | G22: 10.5 | H22: Hours
F23: Shifts | G23: 2
F24: Days / month | G24: 22
F25: Months | G25: 12
F26: MES Capacity | G26: =G21*G22*G23*G24*G25 -> 282744

Sheet 최저임금
B1: 년도별 최저임금 조사자료
B17: 년도 | C17: 2004 | D17: 2005 | E17: 2006 | F17: 2007 | G17: 2008 | H17: 2009 | I17: 2010 | J17: 2011 | K17: 2012 | L17: 2013 | M17: 2014 | N17: 2015 | O17: 2016 | P17: 2017 | Q17: 2018 | R17: 2019 | S17: 2020 | T17: 2021 | U17: 2022
B18: 최저임금 | C18: 2510 | D18: 2840 | E18: 3100 | F18: 3480 | G18: 3770 | H18: 4000 | I18: 4110 | J18: 4320 | K18: 4580 | L18: 4860 | M18: 5210 | N18: 5580 | O18: 6030 | P18: 6470 | Q18: 7530 | R18: 8350 | S18: 8590 | T18: 8720 | U18: 9160
P20: =(P18-O18)/O18 -> 0.072968491 | Q20: =(Q18-P18)/P18 -> 0.16383308 | R20: =(R18-Q18)/Q18 -> 0.10889774 | S20: =(S18-R18)/R18 -> 0.028742515 | T20: =(T18-S18)/S18 -> 0.015133877 | U20: =(U18-T18)/T18 -> 0.050458716
U21: =(U18-Q18)/Q18 -> 0.21646746
U23: Average for last 3 years
U24: =AVERAGE(S20:U20) -> 0.031445036
